<?xml version="1.0"?>
<robot name="abb_simple">

<!-- ================= BASE ================= -->
<link name="base_link">
  <visual>
    <geometry>
      <box size="0.2 0.2 0.1"/>
    </geometry>
    <origin xyz="0 0 -0.05"/>
  </visual>
</link>

<!-- ================= LINK1 ================= -->
<link name="link1">
  <visual>
    <origin xyz="0.075 0 0" rpy="0 1.5708 0"/>
    <geometry>
      <cylinder length="0.15" radius="0.04"/>
    </geometry>
  </visual>
</link>

<joint name="joint1" type="revolute">
  <parent link="base_link"/>
  <child link="link1"/>
  <origin xyz="0.15 0 0.4865" rpy="-1.570796 0 0"/>
  <axis xyz="0 0 1"/>
  <limit lower="-3.14" upper="3.14" effort="100" velocity="2"/>
</joint>

<!-- ================= LINK2 ================= -->
<link name="link2">
  <visual>
    <origin xyz="0.35 0 0" rpy="0 1.5708 0"/>
    <geometry>
      <cylinder length="0.7" radius="0.035"/>
    </geometry>
  </visual>
</link>

<joint name="joint2" type="revolute">
  <parent link="link1"/>
  <child link="link2"/>
  <origin xyz="0.7 0 0" rpy="0 0 -1.570796"/>
  <axis xyz="0 0 1"/>
  <limit lower="-3.14" upper="3.14" effort="100" velocity="2"/>
</joint>

<!-- ================= LINK3 ================= -->
<link name="link3">
  <visual>
    <geometry>
      <sphere radius="0.06"/>
    </geometry>
  </visual>
</link>

<joint name="joint3" type="revolute">
  <parent link="link2"/>
  <child link="link3"/>
  <origin xyz="0 0 0" rpy="-1.570796 0 0"/>
  <axis xyz="0 0 1"/>
  <limit lower="-3.14" upper="3.14" effort="100" velocity="2"/>
</joint>

<!-- ================= LINK4 ================= -->
<link name="link4">
  <visual>
    <origin xyz="0 0 0.3"/>
    <geometry>
      <cylinder length="0.6" radius="0.03"/>
    </geometry>
  </visual>
</link>

<joint name="joint4" type="revolute">
  <parent link="link3"/>
  <child link="link4"/>
  <origin xyz="0 0 0.6" rpy="1.570796 0 0"/>
  <axis xyz="0 0 1"/>
  <limit lower="-3.14" upper="3.14" effort="100" velocity="2"/>
</joint>

<!-- ================= LINK5 ================= -->
<link name="link5">
  <visual>
    <geometry>
      <sphere radius="0.05"/>
    </geometry>
  </visual>
</link>

<joint name="joint5" type="revolute">
  <parent link="link4"/>
  <child link="link5"/>
  <origin xyz="0 0 0" rpy="1.570796 0 3.14159"/>
  <axis xyz="0 0 1"/>
  <limit lower="-3.14" upper="3.14" effort="100" velocity="2"/>
</joint>

<!-- ================= TOOL ================= -->
<link name="tool0">
  <visual>
    <origin xyz="0 0 0.03"/>
    <geometry>
      <cylinder length="0.065" radius="0.02"/>
    </geometry>
  </visual>
</link>

<joint name="joint6" type="revolute">
  <parent link="link5"/>
  <child link="tool0"/>
  <origin xyz="0 0 0.065" rpy="0 0 0"/>
  <axis xyz="0 0 1"/>
  <limit lower="-3.14" upper="3.14" effort="100" velocity="2"/>
</joint>

</robot>
